/home/sam/.local/share/virtualenvs/pudl-gKD-Mnhe/lib/python3.9/site-packages/geopandas/_compat.py:111: UserWarning: The Shapely GEOS version (3.9.1-CAPI-1.14.2) is incompatible with the GEOS version PyGEOS was compiled with (3.10.1-CAPI-1.16.0). Conversions between both will be slow.
  warnings.warn(
Monkeypatching `pandas.read_excel` v2
/nix/store/i6vabb4div9iy6lsl642d86k1q8riasn-python3-3.9.9/lib/python3.9/runpy.py:127: RuntimeWarning: 'pudl.cli' found in sys.modules after import of package 'pudl', but prior to execution of 'pudl.cli'; this may result in unpredictable behaviour
  warn(RuntimeWarning(msg))
2022-02-14 17:22:53 [    INFO] pudl.extract.ferc1:880 Converting extracted FERC Form 1 table fuel_ferc1 into a pandas DataFrame.
Traceback (most recent call last):
  File "/nix/store/i6vabb4div9iy6lsl642d86k1q8riasn-python3-3.9.9/lib/python3.9/runpy.py", line 197, in _run_module_as_main
    return _run_code(code, main_globals, None,
  File "/nix/store/i6vabb4div9iy6lsl642d86k1q8riasn-python3-3.9.9/lib/python3.9/runpy.py", line 87, in _run_code
    exec(code, run_globals)
  File "/home/sam/box/charmonium.cache/benchmark/.repos/pudl/src/pudl/cli.py", line 144, in <module>
    sys.exit(main())
  File "/home/sam/box/charmonium.cache/benchmark/.repos/pudl/src/pudl/cli.py", line 131, in main
    pudl.etl.etl(
  File "/home/sam/box/charmonium.cache/benchmark/.repos/pudl/src/pudl/etl.py", line 391, in etl
    sqlite_dfs.update(_etl_ferc1(datasets["ferc1"], pudl_settings))
  File "/home/sam/box/charmonium.cache/benchmark/.repos/pudl/src/pudl/etl.py", line 198, in _etl_ferc1
    ferc1_raw_dfs = pudl.extract.ferc1.extract(
  File "/home/sam/box/charmonium.cache/benchmark/.repos/pudl/src/pudl/extract/ferc1.py", line 883, in extract
    ferc1_raw_dfs[pudl_table] = ferc1_extract_functions[pudl_table](
  File "/home/sam/box/charmonium.cache/benchmark/.repos/pudl/src/pudl/extract/ferc1.py", line 904, in fuel
    ferc1_meta = get_ferc1_meta(ferc1_engine)
  File "/home/sam/box/charmonium.cache/benchmark/.repos/pudl/src/pudl/extract/ferc1.py", line 799, in get_ferc1_meta
    raise ValueError(
ValueError: No FERC Form 1 tables found. Is the SQLite DB initialized?
